Workbook

Sheet README!
A1: Vinturas ROI Value Model: Summary Description
A2: Version 6.0 Date: October 29, 2025
A3: This document provides a comprehensive overview of the Vinturas ROI Value Model, including input definitions, calculation logic, and formulas. It serves as a reference for users to understand the model's structure and methodology. All parameters and benchmarks are based on 2025 industry data from sources such as Deloitte, McKinsey, IBM, IEA, SBTi, Kearney, PwC, CDP, and others. The model is designed to quantify recurring EBIT impacts, one-time cash benefits, and cost avoidance from adopting the Vinturas platform.
A4: 1. Model Structure Overview
A5: The model consists of five tabs:
A6: User Inputs: Editable fields for company-specific data (highlighted in yellow).
A7: Industry Benchmarks: Pre-filled parameters by industry (highlighted in green).
A8: Derived Metrics: Intermediate calculations based on inputs and benchmarks (highlighted in blue).
A9: Savings & Benefits: Detailed breakdown of financial impacts (highlighted in blue).
A10: Output Summary: Presentation-ready visuals, key metrics, and chain-of-thought explanation.
A11: The model uses dynamic formulas (e.g., VLOOKUP or INDEX/MATCH) to pull industry-specific parameters from the Benchmarks tab. All calculations are scalable with revenue and adjusted for margin to reflect true EBIT impact.
A12: 2. Input Definitions
A13: Inputs are located in the User Inputs tab and drive the model's scaling and customization.
A14: Parameter | B14: Type | C14: Description | D14: Default Value | E14: Valid Range
A15: Industry | B15: Dropdown Selection | C15: Primary industry sector; determines benchmarks and parameters. | D15: Automotive | E15: Automotive, Manufacturing, Technology, Retail, O&G, Food, Life Sciences
A16: Revenue | B16: Numeric | C16: Total annual revenue in USD; scales all calculations. | D16: 833000000 | E16: > 1,000,000
A17: COGS % of Revenue | B17: Decimal | C17: Cost of goods sold as a percentage of revenue; used for base cost derivations. | D17: 0.82 | E17: 0.5 – 0.95
A18: Average Inventory Value | B18: Numeric (Optional) | C18: Inventory value at cost; leave blank for auto-calculation from COGS and DOH. | D18: Blank | E18: ≥ 0
A19: % Logistics Cost (of Revenue) | B19: Decimal | C19: Logistics expenses as a percentage of revenue. | D19: 0.06 | E19: 0.03 – 0.15
A20: % Exception Cost (of Logistics) | B20: Decimal | C20: Exception expenses (expedites/demurrage) as a percentage of logistics costs. | D20: 0.03 | E20: 0.01 – 0.10
A21: Logistic planner FTE
A23: 3. Industry Benchmarks and Parameters
A24: The Benchmarks tab contains pre-filled values for 7 industries, drawn from 2025 sources (e.g., Deloitte for costs, IBM for cyber risks, IEA for emissions). Parameters include exposure rates, reduction potentials, and risk factors. Key examples (full table in Benchmarks tab):
A25: The Benchmarks tab includes all parameters (e.g., reduction %, risks, avoidance probabilities, margin %). Values are pre-filled and sourced from Deloitte, McKinsey, IBM, IEA, SBTi, and others for 2025 accuracy.
A26: Logistics Cost % of Sales: Industry average spend on logistics (e.g., 0.06 for Automotive).
A27: Inventory DOH: Days of inventory on hand (e.g., 55 for Automotive).
A28: Scope 3 Intensity (tCO2e/$M Revenue): Emissions per million USD revenue (e.g., 50 for Automotive).
A29: Margin %: Gross/contribution margin (e.g., 35% for Automotive).
A30: Other Levers: Reduction %, risks, avoidance probabilities (e.g., Cyber Risk 10% for Automotive).
A31: Below is an enhanced version of the complete list of industry benchmarks and parameters used in the Vinturas ROI Value Model. Each parameter includes a formal definition, its source or rationale (where applicable), and an example specific to the Automotive industry (assuming a baseline company with $833 million in annual revenue, unless otherwise specified for clarity). These parameters are stored in the Benchmarks tab of the model and are dynamically pulled via formulas (e.g., VLOOKUP or INDEX/MATCH) to ensure industry-specific calculations. Examples are illustrative and scaled to the baseline for consistency.
A32: The parameters are categorized for readability: Logistics and Transportation, Inventory and Operations, Capital and Risk Management, Efficiency and Reduction Levers, EV-Specific (Automotive Only), ESG and Emissions, and Cybersecurity and Compliance.
A33: Logistics and Transportation Parameters
A34: Parameter | B34: Definition | C34: Example (Automotive Industry)
A35: Logistics cost % of sales | B35: The percentage of total sales revenue allocated to logistics expenses, including transportation, warehousing, and distribution. Source: Deloitte Supply Chain Benchmarks 2025. | C35: For a $833M revenue company, logistics costs are 6% of sales, equaling $49.98M annually.
A36: Customs/demurrage % of freight | B36: The percentage of freight costs attributed to customs duties, delays, or demurrage fees (e.g., port storage penalties). Source: U.S. Bureau of Transportation Statistics (BTS) 2025. | C36: If freight costs are $49.98M, customs/demurrage at 3% equals $1.5M in additional expenses.
A37: Expedited freight % of freight | B37: The percentage of total freight costs spent on expedited or rush shipping to meet urgent demands. Source: Xeneta Logistics Report 2025. | C37: With $49.98M freight, 5% expedited equates to $2.5M for priority deliveries.
A38: Inter-facility transfers % of freight | B38: The percentage of freight costs dedicated to transfers between company facilities (e.g., warehouses or plants). Source: Supply Chain Dive 2025. | C38: For $49.98M freight, 6% inter-facility transfers amount to $3M for internal movements.
A39: Unplanned transfer share | B39: The share of inter-facility transfers that are unplanned or reactive (e.g., due to stockouts). Source: McKinsey Global Logistics 2024. | C39: If inter-facility costs are $3M, a 20% unplanned share results in $600K reactive expenses.
A40: Outbound LTL share | B40: The share of outbound shipments using Less-Than-Truckload (LTL) carriers. Source: BTS Freight Facts 2025. | C40: For outbound shipments, 65% LTL means partial loads dominate distribution.
A41: Avg truck utilization | B41: The average capacity utilization of trucks in the supply chain (e.g., load factor). Source: BTS 2025. | C41: An average of 70% utilization indicates room for 30% optimization in truckloads.
...

Sheet User Inputs
A1: Parameter | B1: Value | C1: Description/Guidance
A2: Industry | B2: Life Sciences | C2: Select from dropdown. Primary industry sector; determines benchmarks.
A3: Revenue | B3: 1400000000 | C3: Annual revenue in consistent currency (e.g., USD). Total sales; positive number.
A4: COGS % of Revenue | B4: 0.53 | C4: % of revenue on cost of goods sold. Ratio as decimal; default from benchmarks if blank.
A5: Average Inventory Value | C5: Inventory at cost. Optional; leave blank for auto-calc from COGS × DOH / 365.
A6: % Logistics Cost (of Revenue) | B6: 0.11 | C6: % of revenue on logistics. Expense ratio as decimal.
A7: % Exception Cost (of Logistics) | B7: 0.05 | C7: % of logistics on exceptions/expedites. Ratio as decimal.
A8: Logistic planner FTE | C8: Optional Value

Sheet Industry Benchmarks
A1: Industry | B1: Logistics cost % of sales | C1: Customs/demurrage % of freight | D1: Expedited freight % of freight | E1: Inter-facility transfers % of freight | F1: Unplanned transfer share | G1: Outbound LTL share | H1: Avg truck utilization | I1: Border/customs dwell (days) | J1: Port-to-DC lead time (days) | K1: ETA accuracy window | L1: OTIF | M1: Inventory DOH | N1: Carrying cost % inventory | O1: Write-offs % inventory | P1: Planners (FTE) | Q1: Manual time share | R1: Capex investment % of sales | S1: Cybersecurity Lever1 penalty | T1: Cybersecurity Lever2 penalty | U1: Cyber penalty risk | V1: Cyber avoidance probability | W1: ESG penalty | X1: ESG risk probability | Y1: ESG avoidance probability | Z1: Inventory Reduction % | AA1: Logistics Reduction % | AB1: Exception Reduction % | AC1: Platform Cost % | AD1: Planner manual time reduction | AE1: Share of saved time to EBIT | AF1: Service uplift % of sales | AG1: Platform cost % of savings | AH1: Alliance efficiency | AI1: EV battery share of inventory | AJ1: EV volatility scenario | AK1: Emission reduction % logistics | AL1: Carbon price (USD/t) | AM1: Europe share of scope3 | AN1: Logistics share of scope3 | AO1: Total Scope3 emissions (t) | AP1: Source_Logistics % | AQ1: Source_Customs % | AR1: Source_Expedited % | AS1: Source_InterFacility % | AT1: Source_Unplanned % | AU1: Source_DOH | AV1: Source_CarryingCost | AW1: Source_WriteOffs | AX1: Source_Planners | AY1: Source_Capex | AZ1: Source_CyberLever1 | BA1: Source_CyberLever2 | BB1: Source_CyberRisk | BC1: Source_ESGPenalty | BD1: Source_ESGRisk | BE1: Source_InventoryRed | BF1: Source_LogisticsRed | BG1: Source_EmissionRed | BH1: Source_CarbonPrice | BI1: Source_Scope3Europe | BJ1: Source_Scope3Logistics | BK1: Source_TotalScope3 | BL1: Description_Logistics % | BM1: Description_Customs % | BN1: Description_Expedited % | BO1: Description_InterFacility % | BP1: Description_Unplanned % | BQ1: Description_DOH | BR1: Description_CarryingCost | BS1: Description_WriteOffs | BT1: Description_Planners | BU1: Description_Capex | BV1: Description_CyberLever1 | BW1: Description_CyberLever2 | BX1: Description_CyberRisk | BY1: Description_ESGPenalty | BZ1: Description_ESGRisk | CA1: Description_InventoryRed | CB1: Description_LogisticsRed | CC1: Description_EmissionRed | CD1: Description_CarbonPrice | CE1: Description_Scope3Europe | CF1: Description_Scope3Logistics | CG1: Description_TotalScope3 | CH1: Margin % | CI1: Customs Red % | CJ1: Logistics Red % | CK1: Expedite Red % | CL1: Planner Manual Red % | CM1: Redeploy % | CN1: Alliance Efficiency % | CO1: Cash Conversion Factor | CP1: DSO Reduction (days) | CQ1: Capex % of Sales | CR1: Capex Avoidance % | CS1: Depreciation Tax Shield % | CT1: Breach Response % of Revenue | CU1: Downtime Hours per Breach | CV1: Hourly Downtime Cost % | CW1: Breach Risk % | CX1: Breach Avoidance % | CY1: Breach Insurance % | CZ1: Disruption Exposure % | DA1: Disruption Probability % | DB1: Disruption Avoidance % | DC1: Disruption Insurance % | DD1: Compliance Exposure % | DE1: Compliance Risk % | DF1: Compliance Avoidance % | DG1: Compliance Insurance % | DH1: Scope3 Intensity (t/$M) | DI1: Emission Reduction % | DJ1: Carbon Price | DK1: Logistics Share of Scope 3 | DL1: ESG Penalty | DM1: ESG Risk % | DN1: ESG Avoid % | DO1: Service Uplift % of Sales | DP1: OOS Penalty Factor | DQ1: Platform Reduction % | DR1: Planner FTE | DS1: Planner Manual Share | DT1: Warehouse Labor % of Sales | DU1: Labor Reduction % Parameter | DV1: ETA Accuracy Improvement Factor | DW1: Freight Cost Sensitivity Factor | DX1: Warehouse Capex % of Logistics Capex Parameter | DY1: EV battery share of inventory | DZ1: EV volatility scenario | EA1: Emission reduction % logistics | EB1: Carbon price (USD/t) | EC1: Europe share of scope3 | ED1: Logistics share of scope3 | EE1: Total Scope3 emissions (t) | EF1: ESG audit penalty (USD) | EG1: Cybersecurity Lever1 penalty | EH1: Cybersecurity Lever2 penalty | EI1: Cyber penalty risk | EJ1: Cyber avoidance probability | EK1: Capex investment % of sales | EL1: Emission Intensity Factor (tCO2e / $M Revenue) | EM1: ESG risk probability | EN1: ESG avoidance probability | EO1: Planners (FTE) | EP1: L2 Penalty per Hour
A2: Automotive | B2: 0.06 | C2: 0.03 | D2: 0.05 | E2: 0.06 | F2: 0.2 | G2: 0.65 | H2: 0.7 | I2: 2.5 | J2: 21 | K2: ±24h | L2: 0.9 | M2: 55 | N2: 0.2 | O2: 0.01 | P2: 20 | Q2: 0.6 | R2: 0.04 | S2: 1000000 | T2: 2000000 | U2: 0.1 | V2: 0.7 | W2: 1000000 | X2: 0.5 | Y2: 0.85 | Z2: 0.05 | AA2: 0.06 | AB2: 0.05 | AC2: 0.15 | AD2: 0.45 | AE2: 0.7 | AF2: 0.0015 | AG2: 0.15 | AH2: 0.15 | AI2: 0.25 | AJ2: 0.15 | AK2: 0.06 | AL2: 85 | AM2: 0.046 | AN2: 0.1 | AO2: 29713000 | AP2: Deloitte 2025 | AQ2: BTS 2025 | AR2: Xeneta 2025 | AS2: Supply Chain Dive 2025 | AT2: McKinsey 2024 | AU2: Kearney 2024 | AV2: Kearney 2024 | AW2: ISM 2024 | AX2: ISM 2024 | AY2: Deloitte 2025 | AZ2: IBM Ponemon 2024 | BA2: IBM 2024 | BB2: IBM 2024 | BC2: PwC 2024 | BD2: McKinsey 2024 | BE2: SBTi 2025 | BF2: SBTi 2025 | BG2: IEA 2025 | BH2: EU ETS 2025 | BI2: CSCMP 2025 | BJ2: CSCMP 2025 | BK2: CSCMP 2025 | BL2: Avg. for auto (JIT-driven) | BM2: Border data (NA ports avg.) | BN2: 15% tariff impact | BO2: Inter-facility transfers | BP2: Geopolitical volatility | BQ2: EV overstock adjustment | BR2: Capital + obsolescence cost | BS2: Obsolescence rate | BT2: FTE per $1B revenue | BU2: Automation investment | BV2: Penalty × Risk × Avoid. Prob. | BW2: Downtime cost | BX2: Breach probability | BY2: Regulatory fine | BZ2: Scope 3 sourcing risk | CA2: 5% inventory optimization | CB2: 6% freight efficiency | CC2: EV shift target | CD2: EU ETS front-month 2025 | CE2: Europe % of global emissions | CF2: Logistics % of Scope 3 | CG2: Total Scope 3 (tCO2e) | CH2: 0.35 | CI2: 0.4 | CJ2: 0.06 | CK2: 0.5 | CL2: 0.45 | CM2: 0.7 | CN2: 0.15 | CO2: 0.9 | CP2: 3 | CQ2: 0.04 | CR2: 0.25 | CS2: 0.21 | CT2: 0.003 | CU2: 48 | CV2: 0.0005 | CW2: 0.1 | CX2: 0.7 | CY2: 0.8 | CZ2: 0.025 | DA2: 0.12 | DB2: 0.65 | DC2: 0.6 | DD2: 0.008 | DE2: 0.12 | DF2: 0.8 | DG2: 0.5 | DH2: 50 | DI2: 0.06 | DJ2: 85 | DK2: 0.1 | DL2: 1000000 | DM2: 0.5 | DN2: 0.85 | DO2: 0.002 | DP2: 0.2 | DQ2: 0.1 | DR2: 20 | DS2: 0.6 | DT2: 0.018 | DU2: 0.3 | DV2: 0.02 | DW2: 0.1 | DX2: 0.25 | DY2: 0.2 | DZ2: 0.2 | EA2: 0.05 | EB2: 85 | EC2: 0.046 | ED2: 0.1 | EE2: 29713000 | EF2: 1000000 | EG2: 1000000 | EH2: 2000000 | EI2: 0.1 | EJ2: 0.7 | EK2: 0.04 | EL2: 50 | EM2: 0.5 | EN2: 0.85 | EO2: 40 | EP2: 41667
A3: Manufacturing | B3: 0.09 | C3: 0.02 | D3: 0.04 | E3: 0.05 | F3: 0.15 | G3: 0.5 | H3: 0.75 | I3: 1 | J3: 15 | K3: ±18h | L3: 0.92 | M3: 65 | N3: 0.18 | O3: 0.015 | P3: 30 | Q3: 0.5 | R3: 0.05 | S3: 500000 | T3: 1000000 | U3: 0.08 | V3: 0.6 | W3: 500000 | X3: 0.4 | Y3: 0.8 | Z3: 0.045 | AA3: 0.05 | AB3: 0.045 | AC3: 0.15 | AD3: 0.4 | AE3: 0.7 | AF3: 0.0012 | AG3: 0.15 | AH3: 0.1 | AI3: 0 | AJ3: 0 | AK3: 0.05 | AL3: 85 | AM3: 0.046 | AN3: 0.08 | AO3: 29713000 | AP3: McKinsey 2024 | AQ3: Supply Chain Dive 2025 | AR3: Supply Chain Dive 2025 | AS3: Supply Chain Dive 2025 | AT3: McKinsey 2024 | AU3: Kearney 2024 | AV3: ISM 2024 | AW3: ISM 2024 | AX3: ISM 2024 | AY3: Deloitte 2025 | AZ3: IBM 2024 | BA3: IBM 2024 | BB3: IBM 2024 | BC3: PwC 2024 | BD3: PwC 2024 | BE3: SBTi 2025 | BF3: SBTi 2025 | BG3: SBTi 2025 | BH3: EU ETS 2025 | BI3: CSCMP 2025 | BJ3: CSCMP 2025 | BK3: CSCMP 2025 | BL3: Adj. for raw mat. inflation | BM3: Inter-facility % | BN3: Inter-facility % | BO3: Inter-facility % | BP3: Overstock trend | BQ3: Overstock adjustment | BR3: Obsolescence | BS3: Obsolescence rate | BT3: FTE per $1B revenue | BU3: Automation focus | BV3: Downtime $1.5M avg. | BW3: Downtime cost | BX3: Breach probability | BY3: Regulatory fine | BZ3: Tech adoption | CA3: 5% baseline adj. | CB3: 5% baseline adj. | CC3: Sector maturity target | CD3: EU ETS front-month 2025 | CE3: Europe % of global emissions | CF3: Logistics % of Scope 3 | CG3: Total Scope 3 (tCO2e) | CH3: 0.3 | CI3: 0.35 | CJ3: 0.05 | CK3: 0.45 | CL3: 0.4 | CM3: 0.7 | CN3: 0.1 | CO3: 0.85 | CP3: 2.5 | CQ3: 0.05 | CR3: 0.2 | CS3: 0.21 | CT3: 0.0025 | CU3: 72 | CV3: 0.0004 | CW3: 0.08 | CX3: 0.6 | CY3: 0.75 | CZ3: 0.03 | DA3: 0.1 | DB3: 0.6 | DC3: 0.55 | DD3: 0.01 | DE3: 0.1 | DF3: 0.75 | DG3: 0.45 | DH3: 35 | DI3: 0.05 | DJ3: 85 | DK3: 0.1 | DL3: 500000 | DM3: 0.4 | DN3: 0.8 | DO3: 0.005 | DP3: 0.2 | DQ3: 0.1 | DR3: 25 | DS3: 0.55 | DT3: 0.022 | DU3: 0.25 | DV3: 0.015 | DW3: 0.08 | DX3: 0.2 | DY3: 0 | DZ3: 0 | EA3: 0.04 | EB3: 85 | EC3: 0.046 | ED3: 0.08 | EE3: 29713000 | EF3: 500000 | EG3: 500000 | EH3: 1000000 | EI3: 0.08 | EJ3: 0.6 | EK3: 0.05 | EL3: 35 | EM3: 0.4 | EN3: 0.8 | EO3: 50 | EP3: 13889
A4: Technology | B4: 0.05 | C4: 0.01 | D4: 0.03 | E4: 0.04 | F4: 0.1 | G4: 0.4 | H4: 0.8 | I4: 0.5 | J4: 10 | K4: ±12h | L4: 0.95 | M4: 40 | N4: 0.15 | O4: 0.006 | P4: 25 | Q4: 0.4 | R4: 0.08 | S4: 250000 | T4: 400000 | U4: 0.06 | V4: 0.75 | W4: 200000 | X4: 0.25 | Y4: 0.9 | Z4: 0.035 | AA4: 0.04 | AB4: 0.035 | AC4: 0.15 | AD4: 0.35 | AE4: 0.75 | AF4: 0.01 | AG4: 0.15 | AH4: 0.05 | AI4: 0 | AJ4: 0 | AK4: 0.04 | AL4: 85 | AM4: 0.046 | AN4: 0.08 | AO4: 29713000 | AP4: Gartner 2025 | AQ4: Qualtrics 2024 | AR4: Qualtrics 2024 | AS4: Qualtrics 2024 | AT4: McKinsey 2024 | AU4: Netstock 2024 | AV4: Netstock 2024 | AW4: Netstock 2024 | AX4: Netstock 2024 | AY4: Deloitte 2025 | AZ4: IBM 2024 | BA4: IBM 2024 | BB4: IBM 2024 | BC4: PwC 2024 | BD4: McKinsey 2024 | BE4: SBTi 2025 | BF4: SBTi 2025 | BG4: IEA 2025 | BH4: EU ETS 2025 | BI4: CSCMP 2025 | BJ4: CSCMP 2025 | BK4: CSCMP 2025 | BL4: Cloud optimization | BM4: ETA window | BN4: OTIF gains | BO4: OTIF gains | BP4: Digital maturity | BQ4: Tech obsolescence | BR4: Obsolescence rate | BS4: Obsolescence rate | BT4: FTE per $1B revenue | BU4: R&D investment | BV4: Tech +15% premium | BW4: Downtime cost | BX4: Breach probability | BY4: Regulatory fine | BZ4: Digital maturity | CA4: 3.5% inventory opt. | CB4: 4% freight efficiency | CC4: Data center focus | CD4: EU ETS front-month 2025 | CE4: Europe % of global emissions | CF4: Logistics % of Scope 3 | CG4: Total Scope 3 (tCO2e) | CH4: 0.5 | CI4: 0.3 | CJ4: 0.04 | CK4: 0.4 | CL4: 0.35 | CM4: 0.75 | CN4: 0.05 | CO4: 0.95 | CP4: 2 | CQ4: 0.07 | CR4: 0.3 | CS4: 0.21 | CT4: 0.004 | CU4: 24 | CV4: 0.0007 | CW4: 0.06 | CX4: 0.75 | CY4: 0.85 | CZ4: 0.018 | DA4: 0.08 | DB4: 0.75 | DC4: 0.7 | DD4: 0.006 | DE4: 0.08 | DF4: 0.85 | DG4: 0.6 | DH4: 140 | DI4: 0.04 | DJ4: 85 | DK4: 0.1 | DL4: 200000 | DM4: 0.25 | DN4: 0.9 | DO4: 0.01 | DP4: 0.2 | DQ4: 0.1 | DR4: 30 | DS4: 0.5 | DT4: 0.012 | DU4: 0.2 | DV4: 0.01 | DW4: 0.06 | DX4: 0.3 | DY4: 0 | DZ4: 0 | EA4: 0.03 | EB4: 85 | EC4: 0.046 | ED4: 0.08 | EE4: 29713000 | EF4: 200000 | EG4: 200000 | EH4: 300000 | EI4: 0.05 | EJ4: 0.5 | EK4: 0.07 | EL4: 140 | EM4: 0.25 | EN4: 0.9 | EO4: 30 | EP4: 16667
A5: Retail | B5: 0.08 | C5: 0.03 | D5: 0.04 | E5: 0.05 | F5: 0.18 | G5: 0.55 | H5: 0.75 | I5: 1.5 | J5: 18 | K5: ±18h | L5: 0.92 | M5: 45 | N5: 0.22 | O5: 0.015 | P5: 40 | Q5: 0.6 | R5: 0.05 | S5: 300000 | T5: 500000 | U5: 0.08 | V5: 0.6 | W5: 300000 | X5: 0.4 | Y5: 0.8 | Z5: 0.05 | AA5: 0.045 | AB5: 0.05 | AC5: 0.15 | AD5: 0.4 | AE5: 0.7 | AF5: 0.004 | AG5: 0.15 | AH5: 0.1 | AI5: 0 | AJ5: 0 | AK5: 0.05 | AL5: 85 | AM5: 0.046 | AN5: 0.07 | AO5: 29713000 | AP5: Xeneta 2025 | AQ5: BTS 2025 | AR5: BTS 2025 | AS5: BTS 2025 | AT5: ISM 2024 | AU5: ISM 2024 | AV5: ISM 2024 | AW5: ISM 2024 | AX5: ISM 2024 | AY5: PwC 2024 | AZ5: PwC 2024 | BA5: PwC 2024 | BB5: PwC 2024 | BC5: PwC 2024 | BD5: SBTi 2025 | BE5: SBTi 2025 | BF5: SBTi 2025 | BG5: EU ETS 2025 | BH5: CSCMP 2025 | BI5: CSCMP 2025 | BJ5: CSCMP 2025 | BK5: E-comm last-mile | BL5: Retail ports dwell | BM5: Retail ports dwell | BN5: Retail ports dwell | BO5: Seasonal volatility | BP5: Seasonal volatility | BQ5: Seasonal volatility | BR5: Seasonal volatility | BS5: FTE per $1B revenue | BT5: Consumer-facing risk | BU5: Regulatory fine | BV5: Regulatory fine | BW5: Regulatory fine | BX5: Regulatory fine | BY5: 5% baseline adj. | BZ5: 4.5% freight efficiency | CA5: Seasonal volatility target | CB5: EU ETS front-month 2025 | CC5: Europe % of global emissions | CD5: Retail Scope 3 | CE5: Total Scope 3 (tCO2e) | CH5: 0.25 | CI5: 0.45 | CJ5: 0.045 | CK5: 0.5 | CL5: 0.4 | CM5: 0.7 | CN5: 0.1 | CO5: 0.8 | CP5: 4 | CQ5: 0.05 | CR5: 0.25 | CS5: 0.21 | CT5: 0.0035 | CU5: 36 | CV5: 0.0006 | CW5: 0.08 | CX5: 0.6 | CY5: 0.7 | CZ5: 0.04 | DA5: 0.15 | DB5: 0.6 | DC5: 0.5 | DD5: 0.012 | DE5: 0.15 | DF5: 0.7 | DG5: 0.4 | DH5: 25 | DI5: 0.05 | DJ5: 85 | DK5: 0.1 | DL5: 300000 | DM5: 0.4 | DN5: 0.8 | DO5: 0.004 | DP5: 0.2 | DQ5: 0.1 | DR5: 28 | DS5: 0.55 | DT5: 0.03 | DU5: 0.35 | DV5: 0.025 | DW5: 0.12 | DX5: 0.3 | DY5: 0 | DZ5: 0 | EA5: 0.05 | EB5: 85 | EC5: 0.046 | ED5: 0.07 | EE5: 29713000 | EF5: 300000 | EG5: 300000 | EH5: 500000 | EI5: 0.08 | EJ5: 0.6 | EK5: 0.05 | EL5: 25 | EM5: 0.4 | EN5: 0.8 | EO5: 25 | EP5: 13889
A6: O&G | B6: 0.1 | C6: 0.02 | D6: 0.03 | E6: 0.04 | F6: 0.12 | G6: 0.45 | H6: 0.8 | I6: 2 | J6: 20 | K6: ±20h | L6: 0.9 | M6: 30 | N6: 0.25 | O6: 0.012 | P6: 15 | Q6: 0.5 | R6: 0.05 | S6: 1000000 | T6: 2000000 | U6: 0.12 | V6: 0.7 | W6: 1000000 | X6: 0.5 | Y6: 0.75 | Z6: 0.045 | AA6: 0.035 | AB6: 0.04 | AC6: 0.15 | AD6: 0.35 | AE6: 0.7 | AF6: 0.006 | AG6: 0.15 | AH6: 0.1 | AI6: 0 | AJ6: 0 | AK6: 0.04 | AL6: 85 | AM6: 0.046 | AN6: 0.06 | AO6: 29713000 | AP6: BTS 2025 | AQ6: Supply Chain Dive 2025 | AR6: Supply Chain Dive 2025 | AS6: Supply Chain Dive 2025 | AT6: Supply Chain Dive 2025 | AU6: Kearney 2024 | AV6: Kearney 2024 | AW6: Kearney 2024 | AX6: Kearney 2024 | AY6: EU CSDDD 2025 | AZ6: IBM 2024 | BA6: IBM 2024 | BB6: IBM 2024 | BC6: EU CSDDD 2025 | BD6: IEA 2025 | BE6: SBTi 2025 | BF6: SBTi 2025 | BG6: IEA 2025 | BH6: EU ETS 2025 | BI6: CSCMP 2025 | BJ6: CSCMP 2025 | BK6: CSCMP 2025 | BL6: High for hazmat | BM6: Geopolitical | BN6: Geopolitical | BO6: Geopolitical | BP6: Geopolitical | BQ6: Volatility | BR6: Volatility | BS6: Volatility | BT6: FTE per $1B revenue | BU6: Reg. scrutiny | BV6: O&G avg. $5.2M | BW6: Downtime cost | BX6: Breach probability | BY6: Reg. scrutiny | BZ6: Energy transition lag | CA6: 4.5% inventory opt. | CB6: 3.5% freight efficiency | CC6: Energy transition lag | CD6: EU ETS front-month 2025 | CE6: Europe % of global emissions | CF6: Logistics % of Scope 3 | CG6: Total Scope 3 (tCO2e) | CH6: 0.4 | CI6: 0.3 | CJ6: 0.035 | CK6: 0.4 | CL6: 0.35 | CM6: 0.7 | CN6: 0.1 | CO6: 0.85 | CP6: 2 | CQ6: 0.05 | CR6: 0.2 | CS6: 0.21 | CT6: 0.0045 | CU6: 96 | CV6: 0.0008 | CW6: 0.12 | CX6: 0.7 | CY6: 0.6 | CZ6: 0.05 | DA6: 0.18 | DB6: 0.7 | DC6: 0.4 | DD6: 0.015 | DE6: 0.18 | DF6: 0.7 | DG6: 0.3 | DH6: 100 | DI6: 0.04 | DJ6: 85 | DK6: 0.1 | DL6: 1000000 | DM6: 0.5 | DN6: 0.75 | DO6: 0.006 | DP6: 0.2 | DQ6: 0.1 | DR6: 22 | DS6: 0.5 | DT6: 0.015 | DU6: 0.25 | DV6: 0.015 | DW6: 0.08 | DX6: 0.2 | DY6: 0 | DZ6: 0 | EA6: 0.04 | EB6: 85 | EC6: 0.046 | ED6: 0.06 | EE6: 29713000 | EF6: 1000000 | EG6: 1000000 | EH6: 2000000 | EI6: 0.12 | EJ6: 0.7 | EK6: 0.05 | EL6: 100 | EM6: 0.5 | EN6: 0.75 | EO6: 60 | EP6: 20833
A7: Food | B7: 0.1 | C7: 0.03 | D7: 0.03 | E7: 0.04 | F7: 0.15 | G7: 0.5 | H7: 0.8 | I7: 0.5 | J7: 12 | K7: ±12h | L7: 0.93 | M7: 18 | N7: 0.3 | O7: 0.012 | P7: 10 | Q7: 0.4 | R7: 0.04 | S7: 500000 | T7: 800000 | U7: 0.1 | V7: 0.6 | W7: 500000 | X7: 0.4 | Y7: 0.8 | Z7: 0.04 | AA7: 0.04 | AB7: 0.04 | AC7: 0.15 | AD7: 0.35 | AE7: 0.7 | AF7: 0.008 | AG7: 0.15 | AH7: 0.1 | AI7: 0 | AJ7: 0 | AK7: 0.04 | AL7: 85 | AM7: 0.046 | AN7: 0.05 | AO7: 29713000 | AP7: Grand View 2025 | AQ7: Kearney 2024 | AR7: Kearney 2024 | AS7: Kearney 2024 | AT7: Netstock 2024 | AU7: Netstock 2024 | AV7: Netstock 2024 | AW7: Netstock 2024 | AX7: Netstock 2024 | AY7: CSCMP 2025 | AZ7: CSCMP 2025 | BA7: CSCMP 2025 | BB7: CSCMP 2025 | BC7: CSCMP 2025 | BD7: SBTi 2025 | BE7: SBTi 2025 | BF7: CSCMP 2025 | BG7: EU ETS 2025 | BH7: CSCMP 2025 | BI7: CSCMP 2025 | BJ7: CSCMP 2025 | BK7: Cold chain | BL7: Perishability | BM7: Perishability | BN7: Perishability | BO7: Automation | BP7: Automation | BQ7: Automation | BR7: Automation | BS7: FTE per $1B revenue | BT7: Food Scope 3 80% | BU7: Regulatory fine | BV7: Downtime cost | BW7: Breach probability | BX7: Regulatory fine | BY7: 4% inventory opt. | BZ7: 4% freight efficiency | CA7: Food Scope 3 80% | CB7: EU ETS front-month 2025 | CC7: Europe % of global emissions | CD7: Direct farm-to-fork | CE7: Total Scope 3 (tCO2e) | CH7: 0.28 | CI7: 0.4 | CJ7: 0.04 | CK7: 0.45 | CL7: 0.35 | CM7: 0.7 | CN7: 0.1 | CO7: 0.8 | CP7: 3.5 | CQ7: 0.04 | CR7: 0.25 | CS7: 0.21 | CT7: 0.0028 | CU7: 48 | CV7: 0.0005 | CW7: 0.1 | CX7: 0.6 | CY7: 0.75 | CZ7: 0.035 | DA7: 0.14 | DB7: 0.6 | DC7: 0.55 | DD7: 0.011 | DE7: 0.14 | DF7: 0.75 | DG7: 0.5 | DH7: 30 | DI7: 0.04 | DJ7: 85 | DK7: 0.1 | DL7: 500000 | DM7: 0.4 | DN7: 0.8 | DO7: 0.008 | DP7: 0.2 | DQ7: 0.1 | DR7: 24 | DS7: 0.55 | DT7: 0.028 | DU7: 0.3 | DV7: 0.02 | DW7: 0.1 | DX7: 0.25 | DY7: 0 | DZ7: 0 | EA7: 0.04 | EB7: 85 | EC7: 0.046 | ED7: 0.05 | EE7: 29713000 | EF7: 500000 | EG7: 500000 | EH7: 800000 | EI7: 0.1 | EJ7: 0.6 | EK7: 0.04 | EL7: 30 | EM7: 0.4 | EN7: 0.8 | EO7: 20 | EP7: 16667
A8: Life Sciences | B8: 0.07 | C8: 0.04 | D8: 0.06 | E8: 0.07 | F8: 0.25 | G8: 0.6 | H8: 0.65 | I8: 3 | J8: 25 | K8: ±36h | L8: 0.88 | M8: 70 | N8: 0.24 | O8: 0.018 | P8: 35 | Q8: 0.65 | R8: 0.06 | S8: 1500000 | T8: 3000000 | U8: 0.15 | V8: 0.8 | W8: 1500000 | X8: 0.6 | Y8: 0.9 | Z8: 0.055 | AA8: 0.07 | AB8: 0.055 | AC8: 0.15 | AD8: 0.5 | AE8: 0.7 | AF8: 0.002 | AG8: 0.15 | AH8: 0.12 | AI8: 0 | AJ8: 0 | AK8: 0.07 | AL8: 85 | AM8: 0.046 | AN8: 0.12 | AO8: 29713000 | AP8: Deloitte Pharma 2025 | AQ8: FDA 2025 | AR8: Xeneta 2025 | AS8: McKinsey Pharma 2024 | AT8: McKinsey 2024 | AU8: Kearney Pharma 2024 | AV8: Kearney 2024 | AW8: ISM Pharma 2024 | AX8: ISM 2024 | AY8: Deloitte 2025 | AZ8: IBM Pharma 2024 | BA8: IBM 2024 | BB8: IBM 2024 | BC8: FDA 2025 | BD8: EMA 2025 | BE8: SBTi Pharma 2025 | BF8: SBTi 2025 | BG8: IEA Pharma 2025 | BH8: EU ETS 2025 | BI8: CSCMP 2025 | BJ8: CSCMP 2025 | BK8: CSCMP 2025 | BL8: Cold chain + clinical trials | BM8: Regulatory delays | BN8: Temperature-controlled expedites | BO8: CDMO transfers | BP8: Trial variability | BQ8: Cold chain LTL | BR8: Refrigerated trucks | BS8: Customs for biologics | BT8: Global trial logistics | BU8: ±36h for stability | BV8: OTIF for patient supply | BW8: High due to R&D inventory | BX8: Capital + obsolescence | BY8: Expiry risk | BZ8: FTE for compliance | CA8: High manual review | CB8: R&D + cold storage | CC8: Breach cost (patient data) | CD8: Downtime (trial halt) | CE8: High regulatory risk | CF8: GxP compliance | CG8: Clinical trial fines | CH8: 0.6 | CI8: 0.5 | CJ8: 0.07 | CK8: 0.55 | CL8: 0.5 | CM8: 0.7 | CN8: 0.12 | CO8: 0.92 | CP8: 3 | CQ8: 0.06 | CR8: 0.3 | CS8: 0.21 | CT8: 0.005 | CU8: 72 | CV8: 0.001 | CW8: 0.15 | CX8: 0.8 | CY8: 0.7 | CZ8: 0.045 | DA8: 0.16 | DB8: 0.8 | DC8: 0.5 | DD8: 0.014 | DE8: 0.16 | DF8: 0.85 | DG8: 0.4 | DH8: 55 | DI8: 0.07 | DJ8: 85 | DK8: 0.1 | DL8: 1500000 | DM8: 0.6 | DN8: 0.9 | DO8: 0.012 | DP8: 0.2 | DQ8: 0.1 | DR8: 35 | DS8: 0.6 | DT8: 0.02 | DU8: 0.35 | DV8: 0.03 | DW8: 0.15 | DX8: 0.3 | DY8: 0 | DZ8: 0 | EA8: 0.04 | EB8: 85 | EC8: 0.046 | ED8: 0.12 | EE8: 29713000 | EF8: 1500000 | EG8: 250000 | EH8: 600000 | EI8: 0.08 | EJ8: 0.6 | EK8: 0.06 | EL8: 55 | EM8: 0.6 | EN8: 0.9 | EO8: 30 | EP8: 41667

Sheet Derived Metrics
A1: Metric | B1: Value | C1: Formula/Logic | D1: Logic | E1: Note | F1: Example
A2: COGS | B2: ='User Inputs'!$B$3*'User Inputs'!$B$4 -> 742000000 | C2: ='User Inputs'!$B$3*'User Inputs'!$B$4 | D2: Revenue × COGS % | E2: Cost of goods sold as a percentage of revenue; used for base cost derivations
A3: Logistics cost % of sales | B3: =IF('User Inputs'!$B$6<>"", 'User Inputs'!$B$3 * 'User Inputs'!$B$6, B2*VLOOKUP('User Inputs'!$B$2,'Industry Benchmarks'!$A:$ZV,2,FALSE)) -> 154000000 | C3: 'IF user provides % Logistics Cost, Revenue × that %, else COGS × benchmark Logistics % (VLOOKUP) | D3: Revenue × Logistics cost % | E3: The percentage of total sales revenue allocated to logistics expenses, including transportation, warehousing, and distribution. Source: Deloitte Supply Chain Benchmarks 2025. | F3: For a $833M revenue company, logistics costs are 6% of sales, equaling $49.98M annually.
A4: Customs/demurrage cost | B4: =B3*VLOOKUP('User Inputs'!$B$2,'Industry Benchmarks'!$A:$ZV,3,FALSE) -> 6160000 | C4: '=B3*VLOOKUP('User Inputs'!$B$2,'Industry Benchmarks'!$A:$ZZ,3,FALSE) | D4: Freight × Customs % | E4: The percentage of freight costs attributed to customs duties, delays, or demurrage fees (e.g., port storage penalties). Source: U.S. Bureau of Transportation Statistics (BTS) 2025. | F4: If freight costs are $49.98M, customs/demurrage at 3% equals $1.5M in additional expenses.
A5: Expedited freight cost | B5: =IF('User Inputs'!$B$7<>"", 'Derived Metrics'!B3 * 'User Inputs'!$B$7, 'Derived Metrics'!B3*VLOOKUP('User Inputs'!$B$2,'Industry Benchmarks'!$A:$ZV,4,FALSE)) -> 7700000 | C5: 'IF user provides % Exception cost of logistics, Freight × user %, else Freight × benchmark expedite % | D5: Freight × Expedite % | E5: The percentage of total freight costs spent on expedited or rush shipping to meet urgent demands. Source: Xeneta Logistics Report 2025. | F5: With $49.98M freight, 5% expedited equates to $2.5M for priority deliveries.
A6: Inter-facility transfer cost | B6: =B3*VLOOKUP('User Inputs'!$B$2,'Industry Benchmarks'!$A:$ZV,5,FALSE) -> 10780000 | C6: '=B3*VLOOKUP('User Inputs'!$B$2,'Industry Benchmarks'!$A:$ZZ,5,FALSE) | D6: Freight × Inter-facility % | E6: The percentage of freight costs dedicated to transfers between company facilities (e.g., warehouses or plants). Source: Supply Chain Dive 2025. | F6: For $49.98M freight, 6% inter-facility transfers amount to $3M for internal movements.
A7: Unplanned transfer cost | B7: =B6*VLOOKUP('User Inputs'!$B$2,'Industry Benchmarks'!$A:$ZV,6,FALSE) -> 2695000 | C7: '=B6*VLOOKUP('User Inputs'!$B$2,'Industry Benchmarks'!$A:$ZZ,6,FALSE) | D7: Inter-facility cost × Unplanned share | E7: The share of inter-facility transfers that are unplanned or reactive (e.g., due to stockouts). Source: McKinsey Global Logistics 2024. | F7: If inter-facility costs are $3M, a 20% unplanned share results in $600K reactive expenses.
A8: Inventory DOH | B8: =IF('User Inputs'!$B$5<>"", ('User Inputs'!$B$5*365)/B2, VLOOKUP('User Inputs'!$B$2,'Industry Benchmarks'!$A:$ZV,13,FALSE)) -> 70 | C8: 'IF user provides Inventory Value, DOH=Inventory×365/COGS else use benchmark DOH | E8: Days of inventory on hand, measuring how long current inventory lasts at average sales rate. Source: Kearney Inventory Insights 2024. | F8: 55 DOH means inventory turns over approximately 6.6 times per year.
A9: Inventory value | B9: =IF('User Inputs'!$B$5<>"", 'User Inputs'!$B$5, B2*B8/365) -> 1.4230137e+08 | C9: 'IF inventory value provided, use it; else COGS×DOH/365 | D9: COGS × DOH /365 or user input | E9: Inventory value at cost; leave blank for auto-calculation from COGS and DOH.
A10: Carrying cost | B10: =B9*VLOOKUP('User Inputs'!$B$2,'Industry Benchmarks'!$A:$ZV,14,FALSE) -> 34152329 | C10: '=B9*VLOOKUP('User Inputs'!$B$2,'Industry Benchmarks'!$A:$ZZ,14,FALSE) | D10: Inventory × Carrying % | E10: The percentage of inventory value spent on holding costs (e.g., storage, insurance). Source: Kearney 2024. | F10: For $100M inventory, 20% carrying cost equals $20M annual holding expense.
A11: Write-offs | B11: =B9*VLOOKUP('User Inputs'!$B$2,'Industry Benchmarks'!$A:$ZV,15,FALSE)*VLOOKUP('User Inputs'!$B$2,'Industry Benchmarks'!$A:$ZV,14,FALSE) -> 614741.92 | C11: '=B9*VLOOKUP('User Inputs'!$B$2,'Industry Benchmarks'!$A:$ZZ,15,FALSE)*VLOOKUP('User Inputs'!$B$2,'Industry Benchmarks'!$A:$ZZ,14,FALSE) | D11: Inventory × Write-off % | E11: The percentage of inventory value lost to obsolescence, damage, or expiration. Source: ISM 2024. | F11: For $100M inventory, 1% write-offs result in $1M annual losses.
A12: Planner payroll | B12: =IF('User Inputs'!$B$8<>"",'User Inputs'!$B$8,VLOOKUP('User Inputs'!$B$2,'Industry Benchmarks'!$A:$ZV,16,FALSE))*60000 -> 2100000 | C12: '=IF('User Inputs'!$B$6<>"",'User Inputs'!$B$6,VLOOKUP('User Inputs'!$B$2,'Industry Benchmarks'!$A:$ZZ,16,FALSE))*60000 | D12: FTE × salary (60k) | E12: Full-time equivalent planners needed for supply chain operations. Source: ISM 2024. | F12: 20 FTE planners for a mid-sized auto firm managing global suppliers.
A13: EV inventory at risk | B13: =B9*VLOOKUP('User Inputs'!$B$2,'Industry Benchmarks'!$A:$ZV,35,FALSE) -> 0 | C13: '=B9*VLOOKUP('User Inputs'!$B$2,'Industry Benchmarks'!$A:$ZZ,35,FALSE) | E13: EV Inventory at Risk = Inventory Value × EV Battery Share of Inventory Automotive-specific EV exposure; for volatility impact. Percentage of inventory value attributed to EV batteries. Source: IEA EV Outlook 2025. | F13: 25% of $100M inventory = $25M in EV batteries.
A14: EV volatility impact | B14: =B13*VLOOKUP('User Inputs'!$B$2,'Industry Benchmarks'!$A:$ZV,36,FALSE) -> 0 | C14: '=B13*VLOOKUP('User Inputs'!$B$2,'Industry Benchmarks'!$A:$ZZ,36,FALSE) | E14: EV Volatility Impact = EV Inventory at Risk × EV Volatility Scenario Price fluctuation risk; automotive only.Percentage risk factor for EV battery price fluctuations. Source: IEA 2025 | F14: 15% volatility on $25M batteries = $3.75M risk exposure.
A15: Total Scope 3 emissions (t) | B15: =('User Inputs'!$B$3/1000000)*VLOOKUP('User Inputs'!$B$2,'Industry Benchmarks'!$A:$ZV,112,FALSE) -> 77000 | C15: =('User Inputs'!$B$3/1000000)*VLOOKUP('User Inputs'!$B$2,'Industry Benchmarks'!$A:$ZZ,109,FALSE) | D15: Revenue/1M × Scope3 Intensity | E15: Total annual Scope 3 GHG emissions in tons CO2e (calculated dynamically). Source: S&P Global 2024.
A16: Reduced tons (Scope 3) | B16: =B15*VLOOKUP('User Inputs'!$B$2,'Industry Benchmarks'!$A:$ZV,40,FALSE)*VLOOKUP('User Inputs'!$B$2,'Industry Benchmarks'!$A:$ZV,110,FALSE) -> 7854 | C16: '=B15*VLOOKUP('User Inputs'!$B$2,'Industry Benchmarks'!$A:$ZZ,40,FALSE)*VLOOKUP('User Inputs'!$B$2,'Industry Benchmarks'!$A:$ZZ,110,FALSE) | D16: Total Scope3 × Logistics share × Emission Red % | E16: Percentage reduction in logistics emissions via optimization. Source: IEA 2025.
A17: Emission benefit (USD) | B17: =B16*VLOOKUP('User Inputs'!$B$2,'Industry Benchmarks'!$A:$ZV,114,FALSE) -> 667590 | C17: '=B16*VLOOKUP('User Inputs'!$B$2,'Industry Benchmarks'!$A:$ZZ,111,FALSE) | D17: Reduced tons × Carbon Price
A18: ESG audit benefit (USD) | B18: =VLOOKUP('User Inputs'!$B$2,'Industry Benchmarks'!$A:$ZV,116,FALSE)*VLOOKUP('User Inputs'!$B$2,'Industry Benchmarks'!$A:$ZV,117,FALSE)*VLOOKUP('User Inputs'!$B$2,'Industry Benchmarks'!$A:$ZV,118,FALSE) -> 810000 | C18: '=VLOOKUP('User Inputs'!$B$2,'Industry Benchmarks'!$A:$ZZ,112,FALSE)*VLOOKUP('User Inputs'!$B$2,'Industry Benchmarks'!$A:$ZZ,113,FALSE)*VLOOKUP('User Inputs'!$B$2,'Industry Benchmarks'!$A:$ZZ,114,FALSE) | D18: ESG penalty × ESG risk × ESG avoid | E18: Average penalty for ESG non-compliance or audit failure. Source: PwC ESG 2025.
A19: Scope 3 Intensity (t per $M) | B19: =VLOOKUP('User Inputs'!$B$2,'Industry Benchmarks'!$A:$ZV,112,FALSE) -> 55 | C19: '=VLOOKUP('User Inputs'!$B$2,'Industry Benchmarks'!$A:$ZZ,109,FALSE) | E19: Annual probability of incurring an ESG penalty. Source: CDP 2025.
F20: $1M for a mid-sized data breach response.
A21: Cyber security Lever 1 (Avoided Breach Response Costs) | B21: =VLOOKUP('User Inputs'!$B$2,'Industry Benchmarks'!$A:$ZV,19,FALSE) -> 1500000 | C21: '=VLOOKUP('User Inputs'!$B$2,'Industry Benchmarks'!$A:$ZZ,19,FALSE) | D21: Lever 1 (Breach Response): Probability = 0.4 (benchmark gap); Impact = $7M (adjusted healthcare average); Avoidance Factor = 0.3 (from JSP integration). EVAC = 0.4 × $7M × 0.3 = $0.84M annually. | E21: Penalty for breach response (e.g., notification, forensics). Source: IBM Cost of a Data Breach 2025. | F21: $2M for 48 hours of assembly line halt.
A22: Cyber security Lever 2 (Downtime) | B22: =VLOOKUP('User Inputs'!$B$2,'Industry Benchmarks'!$A:$ZV,20,FALSE) -> 3000000 | C22: '=VLOOKUP('User Inputs'!$B$2,'Industry Benchmarks'!$A:$ZZ,20,FALSE) | D22: Lever 2 (Downtime): Probability = 0.35; Impact = $2M/day × 3 days; Avoidance Factor = 0.25. EVAC = 0.35 × $6M × 0.25 = $0.525M. | E22: Penalty for downtime losses during a breach. Source: IBM 2025. | F22: 10% risk means 1 in 10 chance per year.
A23: Capex investment % of sales | B23: ='User Inputs'!$B$3*VLOOKUP('User Inputs'!$B$2,'Industry Benchmarks'!$A:$ZV,18,FALSE) -> 84000000 | C23: '=VLOOKUP('User Inputs'!$B$2,'Industry Benchmarks'!$A:$ZZ,18,FALSE)
A24: Avg truck utilization | B24: =VLOOKUP('User Inputs'!$B$2,'Industry Benchmarks'!$A:$ZV,8,FALSE) -> 0.65 | C24: '=VLOOKUP('User Inputs'!$B$2,'Industry Benchmarks'!$A:$ZZ,8,FALSE)
A25: Border/customs dwell (days) | B25: =VLOOKUP('User Inputs'!$B$2,'Industry Benchmarks'!$A:$ZV,9,FALSE) -> 3 | C25: '=VLOOKUP('User Inputs'!$B$2,'Industry Benchmarks'!$A:$ZZ,9,FALSE)
A26: Port-to-DC lead time (days) | B26: =VLOOKUP('User Inputs'!$B$2,'Industry Benchmarks'!$A:$ZV,10,FALSE) -> 25 | C26: '=VLOOKUP('User Inputs'!$B$2,'Industry Benchmarks'!$A:$ZZ,10,FALSE)
A27: ETA accuracy window | B27: =VLOOKUP('User Inputs'!$B$2,'Industry Benchmarks'!$A:$ZV,11,FALSE) -> ±36h | C27: '=VLOOKUP('User Inputs'!$B$2,'Industry Benchmarks'!$A:$ZZ,11,FALSE)
A28: OTIF | B28: =VLOOKUP('User Inputs'!$B$2,'Industry Benchmarks'!$A:$ZV,12,FALSE) -> 0.88 | C28: '=VLOOKUP('User Inputs'!$B$2,'Industry Benchmarks'!$A:$ZZ,12,FALSE)
A30: Inventory Reduction % | B30: =VLOOKUP('User Inputs'!$B$2,'Industry Benchmarks'!$A:$ZV,26,FALSE) -> 0.055 | C30: '=VLOOKUP('User Inputs'!$B$2,'Industry Benchmarks'!$A:$ZZ,26,FALSE) | E30: Percentage reduction in inventory levels via optimization. Source: SBTi 2025. | F30: 5% reduction on $100M inventory frees $5M in capital.
A31: Logistics Reduction % | B31: =VLOOKUP('User Inputs'!$B$2,'Industry Benchmarks'!$A:$ZV,27,FALSE) -> 0.07 | C31: '=VLOOKUP('User Inputs'!$B$2,'Industry Benchmarks'!$A:$ZZ,27,FALSE) | E31: Percentage savings in logistics costs through efficiency. Source: SBTi 2025. | F31: 6% reduction on $50M logistics saves $3M annually.
A32: Exception Reduction % | B32: =VLOOKUP('User Inputs'!$B$2,'Industry Benchmarks'!$A:$ZV,28,FALSE) -> 0.055 | C32: '=VLOOKUP('User Inputs'!$B$2,'Industry Benchmarks'!$A:$ZZ,28,FALSE) | E32: Percentage decrease in exception costs (e.g., expedites). Source: SBTi 2025. | F32: 5% reduction on $2.5M exceptions saves $125K.
A33: Planner manual time reduction | B33: =VLOOKUP('User Inputs'!$B$2,'Industry Benchmarks'!$A:$ZV,30,FALSE) -> 0.5 | C33: '=VLOOKUP('User Inputs'!$B$2,'Industry Benchmarks'!$A:$ZZ,30,FALSE) | E33: Percentage reduction in manual planning time. Source: Netstock 2024. | F33: 45% reduction frees 4.5 hours/day per planner.
A34: Share of saved time redeployed to EBIT | B34: =VLOOKUP('User Inputs'!$B$2,'Industry Benchmarks'!$A:$ZV,31,FALSE) -> 0.7 | C34: '=VLOOKUP('User Inputs'!$B$2,'Industry Benchmarks'!$A:$ZZ,31,FALSE) | E34: Percentage of saved planner time redirected to value-adding activities. Source: McKinsey 2024. | F34: 70% redeploy means 7/10 saved hours boost EBIT.
A35: Service uplift – revenue protect (% of sales) | B35: =VLOOKUP('User Inputs'!$B$2,'Industry Benchmarks'!$A:$ZV,32,FALSE) -> 0.002 | C35: '=VLOOKUP('User Inputs'!$B$2,'Industry Benchmarks'!$A:$ZZ,32,FALSE) | E35: Percentage of revenue protected through better service (e.g., OTIF uplift). Source: Qualtrics 2024. | F35: 0.15% uplift on $833M protects $1.25M in revenue.
A36: Alliance efficiency (inter-facility reduction) | B36: =VLOOKUP('User Inputs'!$B$2,'Industry Benchmarks'!$A:$ZV,34,FALSE) -> 0.12 | C36: '=VLOOKUP('User Inputs'!$B$2,'Industry Benchmarks'!$A:$ZZ,34,FALSE) | E36: Percentage reduction in inter-facility transfer costs via partnerships. Source: Supply Chain Dive 2025. | F36: 15% reduction on $3M transfers saves $450K.
A37: Cybersecurity impact L1 (breach average of industry) | B37: =VLOOKUP('User Inputs'!$B$2,'Industry Benchmarks'!$A:$ZV,19,FALSE) -> 1500000 | C37: '=VLOOKUP('User Inputs'!$B$2,'Industry Benchmarks'!$A:$ZZ,19,FALSE)
A38: Cybersecurity Lever 2 (Downtime): Impact = by industry | B38: =VLOOKUP('User Inputs'!$B$2,'Industry Benchmarks'!$A:$ZV,20,FALSE) -> 3000000 | C38: '=VLOOKUP('User Inputs'!$B$2,'Industry Benchmarks'!$A:$ZZ,20,FALSE)
A39: Supply chain Disruptions impact by industry | B39: =VLOOKUP('User Inputs'!$B$2,'Industry Benchmarks'!$A:$ZV,23,FALSE) -> 1500000 | C39: '=VLOOKUP('User Inputs'!$B$2,'Industry Benchmarks'!$A:$ZZ,23,FALSE) | E39: Calculation: EVAC = Probability (0.4, per MDIC supply chain maturity gap) × Impact ($10-20M for MedTech disruption) × Avoidance Factor (0.3 via contracts). Example: $1.2-2.4M annually
A40: Regulatory complinace impact by industry | B40: =VLOOKUP('User Inputs'!$B$2,'Industry Benchmarks'!$A:$ZV,23,FALSE) -> 1500000 | C40: '=VLOOKUP('User Inputs'!$B$2,'Industry Benchmarks'!$A:$ZZ,23,FALSE) | E40: Levers: Avoided FDA recalls/fines, streamlined audits via NIST integration.
E41: Calculation: EVAC = Probability (0.25, benchmark non-compliance rate) × Impact ($5M average fine) × Avoidance Factor (0.4 from maturity lift). Example: $0.5M annually.

Sheet Savings & Benefits
A1: Impact Item | B1: Value | C1: Formula
A2: Recurring: Service Uplift (Penalty Avoid/Rev Protect) | B2: ='User Inputs'!$B$3 * VLOOKUP('User Inputs'!$B$2,'Industry Benchmarks'!$A:$ZW,119,FALSE) * VLOOKUP('User Inputs'!$B$2,'Industry Benchmarks'!$A:$ZW,120,FALSE) * VLOOKUP('User Inputs'!$B$2,'Industry Benchmarks'!$A:$ZW,121,FALSE) * VLOOKUP('User Inputs'!$B$2,'Industry Benchmarks'!$A:$ZW,86,FALSE) -> 201600 | C2: Revenue * Service Uplift % * OOS Penalty Factor * Platform Reduction % * Industry Margin %
A3: Recurring: Warehouse labor efficiency | B3: ='User Inputs'!$B$3 * VLOOKUP('User Inputs'!$B$2,'Industry Benchmarks'!$A:$ZW,124,FALSE)* VLOOKUP('User Inputs'!$B$2,'Industry Benchmarks'!$A:$ZW,90,FALSE) * VLOOKUP('User Inputs'!$B$2,'Industry Benchmarks'!$A:$ZW,28,FALSE)* VLOOKUP('User Inputs'!$B$2,'Industry Benchmarks'!$A:$ZW,86,FALSE) -> 462000 | C3: Revenue × Warehouse Labor % of Sales × Labor Reduction % × Exception Reduction % × Margin %
A4: Recurring: Customs/Demurrage Savings | B4: ='Derived Metrics'!$B$4 * VLOOKUP('User Inputs'!$B$2,'Industry Benchmarks'!$A:$ZW,87,FALSE) * VLOOKUP('User Inputs'!$B$2,'Industry Benchmarks'!$A:$ZW,28,FALSE)* VLOOKUP('User Inputs'!$B$2,'Industry Benchmarks'!$A:$ZW,86,FALSE) -> 101640 | C4: Customs/demurrage cost × Customs Reduction % × Exception Reduction % × Margin %
A5: Recurring: Freight Savings | B5: ='Derived Metrics'!$B$3 * VLOOKUP('User Inputs'!$B$2,'Industry Benchmarks'!$A:$ZW,27,FALSE) * VLOOKUP('User Inputs'!$B$2,'Industry Benchmarks'!$A:$ZW,126,FALSE)* VLOOKUP('User Inputs'!$B$2,'Industry Benchmarks'!$A:$ZW,86,FALSE) -> 194040 | C5: Freight Cost × (Logistics Reduction % by industry + ETA Accuracy Improvement Factor) × Margin %
A6: Recurring: Expedite Savings | B6: ='Derived Metrics'!$B$5 * VLOOKUP('User Inputs'!$B$2,'Industry Benchmarks'!$A:$ZW,28,FALSE) * VLOOKUP('User Inputs'!$B$2,'Industry Benchmarks'!$A:$ZW,86,FALSE) -> 254100 | C6: Freight Cost × Expedited Freight % of Freight × Exception Reduction % × Margin %
A7: Recurring: Planner Productivity (EBIT) | B7: =(IF('User Inputs'!$B$8<>"", 'User Inputs'!$B$8, VLOOKUP('User Inputs'!$B$2,'Industry Benchmarks'!$A:$ZW,16,FALSE)))*60000 * VLOOKUP('User Inputs'!$B$2,'Industry Benchmarks'!$A:$ZW,17,FALSE)*VLOOKUP('User Inputs'!$B$2,'Industry Benchmarks'!$A:$ZW,30,FALSE) * VLOOKUP('User Inputs'!$B$2,'Industry Benchmarks'!$A:$ZW,31,FALSE) -> 477750 | C7: Planners (FTE) × Average Salary × Manual time share x Planner Manual Time Reduction × Share of Saved Time to EBIT | D7: based on fixed $60K salary
A8: Reduced carrying cost | B8: =('Derived Metrics'!$B$9 * VLOOKUP('User Inputs'!$B$2,'Industry Benchmarks'!$A:$ZW,14,FALSE))/365 * VLOOKUP('User Inputs'!$B$2,'Industry Benchmarks'!$A:$ZW,9,FALSE) -> 280704.07 | C8: Inventory Value × Carrying Cost % of Inventory × Inventory Reduction % | D8: Reduced Carrying Cost = ((Inventory Value × Annual Carrying Cost %) / 365) × (Days Reduced=Border/customs dwell (days))
A9: Reduced write-offs | B9: ='Derived Metrics'!$B$11 * VLOOKUP('User Inputs'!$B$2,'Industry Benchmarks'!$A:$ZW,27,FALSE) -> 43031.934 | C9: Inventory Value × Write-offs % of Inventory × Inventory Reduction % | D9: Reduced Carrying Cost = ((Inventory Value × Annual Carrying Cost %) / 365) × (Days Reduced=Border/customs dwell (days))
A10: Reduced internal transfers | B10: ='Derived Metrics'!$B$6 * VLOOKUP('User Inputs'!$B$2,'Industry Benchmarks'!$A:$ZW,92,FALSE)* VLOOKUP('User Inputs'!$B$2,'Industry Benchmarks'!$A:$ZW,86,FALSE) -> 776160 | C10: Freight Cost x Inter-facility transfers % of freight *Exception Reduction % × Margin %
A11: Total Recurring EBIT Impact | B11: =SUM(B2:B10) -> 2791026 | C11: Service Uplift (Penalty Avoid/Rev Protect) +Warehouse labor efficiency+ Customs/Demurrage Savings+Freight Savings+Expedite Savings+Planner Productivity (EBIT)+Reduced carrying cost+Reduced write-offs+Reduced internal transfers
A13: One-time Cash: Inventory Release | B13: ='Derived Metrics'!$B$9 * VLOOKUP('User Inputs'!$B$2,'Industry Benchmarks'!$A:$ZW,27,FALSE) -> 9961095.9 | C13: Inventory Value × Inventory Reduction % | D13: One-time Cash: Inventory Release = Inventory Value × (DOH Reduction / Current DOH) | M13: ='Derived Metrics'!$B$9*(VLOOKUP('User Inputs'!$B$2,'Industry Benchmarks'!$A:$ZW,9,FALSE)/VLOOKUP('User Inputs'!$B$2,'Industry Benchmarks'!$A:$ZW,13,FALSE)) -> 6098630.1
A14: One-time Cash: Receivables improvement | B14: ='User Inputs'!$B$3 * VLOOKUP('User Inputs'!$B$2,'Industry Benchmarks'!$A:$ZW,94,FALSE)/365 * (1 - VLOOKUP('User Inputs'!$B$2,'Industry Benchmarks'!$A:$ZW,86,FALSE)) * VLOOKUP('User Inputs'!$B$2,'Industry Benchmarks'!$A:$ZW,93,FALSE) -> 4234520.5 | C14: Revenue × DSO Reduction / 365 × (1 - Margin %) × Cash Conversion Factor | D14: for calculation only.. Exclude from benefits
A15: Total One-time Cash Benefit | B15: =B13 -> 9961095.9
A17: Cost Avoidance: Capex Avoidance | B17: ='User Inputs'!$B$3 * VLOOKUP('User Inputs'!$B$2,'Industry Benchmarks'!$A:$ZW,95,FALSE) * VLOOKUP('User Inputs'!$B$2,'Industry Benchmarks'!$A:$ZW,128,FALSE) * VLOOKUP('User Inputs'!$B$2,'Industry Benchmarks'!$A:$ZW,96,FALSE)* (1 - VLOOKUP('User Inputs'!$B$2,'Industry Benchmarks'!$A:$ZW,97,FALSE)) -> 5972400 | C17: (Capex % of Sales × Revenue) × (Warehouse Capex % of Logistics Capex) × Capex Avoidance % × (1 - Depreciation Tax Shield %)
A18: Cost Avoidance: Cyber security Lever 1 (Avoided Breach Response Costs) | B18: ='User Inputs'!$B$3 * VLOOKUP('User Inputs'!$B$2,'Industry Benchmarks'!$A:$ZW,98,FALSE) * VLOOKUP('User Inputs'!$B$2,'Industry Benchmarks'!$A:$ZW,101,FALSE) * VLOOKUP('User Inputs'!$B$2,'Industry Benchmarks'!$A:$ZW,102,FALSE) * (1 - VLOOKUP('User Inputs'!$B$2,'Industry Benchmarks'!$A:$ZW,103,FALSE)) -> 252000 | C18: Revenue × Breach Response % of Revenue × Breach Risk % × Avoidance Probability % × (1 - Insurance Recovery %) | D18: = Cybersecurity Lever1 Penalty * Cyber Penalty Risk * Cyber Avoidance Probability | M18: =VLOOKUP('User Inputs'!$B$2,'Industry Benchmarks'!$A:$ZW,137,FALSE) * VLOOKUP('User Inputs'!$B$2,'Industry Benchmarks'!$A:$ZW,140,FALSE) * VLOOKUP('User Inputs'!$B$2,'Industry Benchmarks'!$A:$ZW,140,FALSE) -> 90000
A19: Cost Avoidance: Cyber security Lever 2 (Downtime) | B19: ='User Inputs'!$B$3 * (VLOOKUP('User Inputs'!$B$2,'Industry Benchmarks'!$A:$ZW,99,FALSE)/8760) * VLOOKUP('User Inputs'!$B$2,'Industry Benchmarks'!$A:$ZW,100,FALSE) * VLOOKUP('User Inputs'!$B$2,'Industry Benchmarks'!$A:$ZW,101,FALSE) * VLOOKUP('User Inputs'!$B$2,'Industry Benchmarks'!$A:$ZW,102,FALSE) * (1 - VLOOKUP('User Inputs'!$B$2,'Industry Benchmarks'!$A:$ZW,103,FALSE)) -> 414.24658 | C19: Revenue × (Downtime Hours per Breach / 8760) × Hourly Downtime Cost % × Breach Risk % × Avoidance Probability % × (1 - Insurance Recovery %) | D19: =Cybersecurity Lever2 Penalty × Cyber Penalty Risk × Cyber Avoidance Probability | M19: =VLOOKUP('User Inputs'!$B$2,'Industry Benchmarks'!$A:$ZW,138,FALSE) * VLOOKUP('User Inputs'!$B$2,'Industry Benchmarks'!$A:$ZW,140,FALSE) * VLOOKUP('User Inputs'!$B$2,'Industry Benchmarks'!$A:$ZW,141,FALSE) -> 21600 | N19: Revenue × (Breach Duration / 8760) × (Lever 2 Penalty / Breach Duration) × Breach Risk % × Avoidance Probability % | Q19: =(VLOOKUP('User Inputs'!$B$2,'Industry Benchmarks'!$A:$ZW,99,FALSE)/8760) * (VLOOKUP('User Inputs'!$B$2,'Industry Benchmarks'!$A:$ZW,138,FALSE)/VLOOKUP('User Inputs'!$B$2,'Industry Benchmarks'!$A:$ZW,99,FALSE))* VLOOKUP('User Inputs'!$B$2,'Industry Benchmarks'!$A:$ZW,140,FALSE) * VLOOKUP('User Inputs'!$B$2,'Industry Benchmarks'!$A:$ZW,141,FALSE) -> 2.4657534 | R19: Breach Duration x L2 Penalty per Hour x Cyber Penalty Risk × Cyber Avoidance Probability | S19: =(VLOOKUP('User Inputs'!$B$2,'Industry Benchmarks'!$A:$ZW,99,FALSE)*(VLOOKUP('User Inputs'!$B$2,'Industry Benchmarks'!$A:$ZW,146,FALSE)*VLOOKUP('User Inputs'!$B$2,'Industry Benchmarks'!$A:$ZW,140,FALSE)*VLOOKUP('User Inputs'!$B$2,'Industry Benchmarks'!$A:$ZW,141,FALSE))) -> 108000.86
A20: Cost Avoidance: Supply chain Disruptions | B20: ='User Inputs'!$B$3 * VLOOKUP('User Inputs'!$B$2,'Industry Benchmarks'!$A:$ZW,104,FALSE) * VLOOKUP('User Inputs'!$B$2,'Industry Benchmarks'!$A:$ZW,105,FALSE) * VLOOKUP('User Inputs'!$B$2,'Industry Benchmarks'!$A:$ZW,106,FALSE) * (1 - VLOOKUP('User Inputs'!$B$2,'Industry Benchmarks'!$A:$ZW,107,FALSE)) -> 4032000 | C20: Revenue × Disruption Exposure % × Disruption Probability % × Avoidance Probability % × (1 - Insurance Recovery %)
A21: Cost Avoidance: Regulatory compliance | B21: ='User Inputs'!$B$3 * VLOOKUP('User Inputs'!$B$2,'Industry Benchmarks'!$A:$ZW,108,FALSE) * VLOOKUP('User Inputs'!$B$2,'Industry Benchmarks'!$A:$ZW,109,FALSE) * VLOOKUP('User Inputs'!$B$2,'Industry Benchmarks'!$A:$ZW,110,FALSE) * (1 - VLOOKUP('User Inputs'!$B$2,'Industry Benchmarks'!$A:$ZW,111,FALSE)) -> 1599360 | C21: Revenue × Compliance Exposure % × Compliance Risk % × Avoidance Probability % × (1 - Insurance Recovery %)
A23: Emission benefit (USD) | B23: ='Derived Metrics'!$B$17 -> 667590 | C23: Reduced Tons (Scope 3) × Carbon Price (USD/t)
A24: ESG audit benefit (USD) | B24: ='Derived Metrics'!$B$18 -> 810000 | C24: ESG Penalty × ESG Risk Probability × ESG Avoidance Probability
A25: Total One-time Cost Avoidance | B25: =B18+B23+B24+B19 -> 1730004.2 | C25: Capex Avoidance+Cyber security Lever 1+Cyber security Lever 2+ Supply chain Disruptions+Regulatory compliance+Emission benefit+ESG audit benefit
A30: Total Savings | B30: =B11 -> 2791026
A31: Net Recurring EBIT after Platform Cost | B31: =B11 - (B30 * VLOOKUP('User Inputs'!$B$2,'Industry Benchmarks'!$A:$ZW,33,FALSE)) -> 2372372.1 | C31: Net Recurring EBIT after Platform Cost= Total Recurring EBIT Impact - (Total Savings × Platform Cost %) | D31: {=Total Recurring EBIT Impact - (Total Savings * Platform Cost %)} -> #NAME?
A32: ROI (3-Year) | B32: =IF($B$33="", "", (B31*3 - $B$33)/$B$33*100) -> 5000 | C32: ROI (3-Year ROI for multi-year view): ROI= ((Net Recurring EBIT × 3) - Initial Implementation Cost) / Initial Implementation Cost × 100
A33: Initial Implementation Cost | B33: =5%*B11 -> 139551.3

Sheet Summary
A1: Parameter | B1: Company Value | C1: Industry Benchmark | D1: Notes
A2: Revenue | B2: ='User Inputs'!$B$3 -> 1400000000 | D2: User provided revenue input
A3: COGS % of Revenue | B3: ='User Inputs'!$B$4 -> 0.53 | D3: User provided COGS ratio input
A4: Logistics cost % of sales | B4: ='User Inputs'!$B$6 -> 0.11 | C4: =INDEX('Industry Benchmarks'!$B$2:$B$8, MATCH('User Inputs'!$B$2, 'Industry Benchmarks'!$A$2:$A$8, 0)) -> 0.07 | D4: Logistics cost ratio input vs benchmark
A5: Customs/demurrage % of freight | C5: =INDEX('Industry Benchmarks'!$C$2:$C$8, MATCH('User Inputs'!$B$2, 'Industry Benchmarks'!$A$2:$A$8, 0)) -> 0.04 | D5: Benchmark customs and demurrage ratio
A6: Expedited freight % of freight | C6: =INDEX('Industry Benchmarks'!$D$2:$D$8, MATCH('User Inputs'!$B$2, 'Industry Benchmarks'!$A$2:$A$8, 0)) -> 0.06 | D6: Benchmark expedited freight ratio
A7: Inter-facility transfers % of freight | C7: =INDEX('Industry Benchmarks'!$E$2:$E$8, MATCH('User Inputs'!$B$2, 'Industry Benchmarks'!$A$2:$A$8, 0)) -> 0.07 | D7: Benchmark inter-facility transfer ratio
A8: Unplanned transfer share | C8: =INDEX('Industry Benchmarks'!$F$2:$F$8, MATCH('User Inputs'!$B$2, 'Industry Benchmarks'!$A$2:$A$8, 0)) -> 0.25 | D8: Share of transfers that are unplanned
A9: Inventory DOH | B9: ='Derived Metrics'!B8 -> 70 | C9: =INDEX('Industry Benchmarks'!$G$2:$G$8, MATCH('User Inputs'!$B$2, 'Industry Benchmarks'!$A$2:$A$8, 0)) -> 0.6 | D9: Days of inventory on hand
A10: Carrying cost % of inventory | C10: =INDEX('Industry Benchmarks'!$H$2:$H$8, MATCH('User Inputs'!$B$2, 'Industry Benchmarks'!$A$2:$A$8, 0)) -> 0.65 | D10: Assumed carrying cost
A11: Write-offs % of inventory | C11: =INDEX('Industry Benchmarks'!$I$2:$I$8, MATCH('User Inputs'!$B$2, 'Industry Benchmarks'!$A$2:$A$8, 0)) -> 3 | D11: Assumed write-off ratio
A12: Inventory Reduction % | B12: =INDEX('Industry Benchmarks'!$J$2:$J$8, MATCH('User Inputs'!$B$2, 'Industry Benchmarks'!$A$2:$A$8, 0)) -> 25 | C12: =INDEX('Industry Benchmarks'!$J$2:$J$8, MATCH('User Inputs'!$B$2, 'Industry Benchmarks'!$A$2:$A$8, 0)) -> 25 | D12: Lever for reducing inventory
A13: Logistics Reduction % | B13: =INDEX('Industry Benchmarks'!$K$2:$K$8, MATCH('User Inputs'!$B$2, 'Industry Benchmarks'!$A$2:$A$8, 0)) -> ±36h | C13: =INDEX('Industry Benchmarks'!$K$2:$K$8, MATCH('User Inputs'!$B$2, 'Industry Benchmarks'!$A$2:$A$8, 0)) -> ±36h | D13: Lever for reducing logistics cost
A14: Exception Reduction % | B14: =INDEX('Industry Benchmarks'!$L$2:$L$8, MATCH('User Inputs'!$B$2, 'Industry Benchmarks'!$A$2:$A$8, 0)) -> 0.88 | C14: =INDEX('Industry Benchmarks'!$L$2:$L$8, MATCH('User Inputs'!$B$2, 'Industry Benchmarks'!$A$2:$A$8, 0)) -> 0.88 | D14: Lever for reducing exceptions/expedites
A15: Planner manual time reduction | B15: =INDEX('Industry Benchmarks'!$M$2:$M$8, MATCH('User Inputs'!$B$2, 'Industry Benchmarks'!$A$2:$A$8, 0)) -> 70 | C15: =INDEX('Industry Benchmarks'!$M$2:$M$8, MATCH('User Inputs'!$B$2, 'Industry Benchmarks'!$A$2:$A$8, 0)) -> 70 | D15: Reduction in planner manual time
A16: Share of saved time redeployed to EBIT | B16: =INDEX('Industry Benchmarks'!$N$2:$N$8, MATCH('User Inputs'!$B$2, 'Industry Benchmarks'!$A$2:$A$8, 0)) -> 0.24 | C16: =INDEX('Industry Benchmarks'!$N$2:$N$8, MATCH('User Inputs'!$B$2, 'Industry Benchmarks'!$A$2:$A$8, 0)) -> 0.24 | D16: Fraction of saved time impacting EBIT
A17: Service uplift % of sales | B17: =INDEX('Industry Benchmarks'!$O$2:$O$8, MATCH('User Inputs'!$B$2, 'Industry Benchmarks'!$A$2:$A$8, 0)) -> 0.018 | C17: =INDEX('Industry Benchmarks'!$O$2:$O$8, MATCH('User Inputs'!$B$2, 'Industry Benchmarks'!$A$2:$A$8, 0)) -> 0.018 | D17: Revenue protect/pentaly avoidance uplift
A18: Platform Cost % | B18: =INDEX('Industry Benchmarks'!$P$2:$P$8, MATCH('User Inputs'!$B$2, 'Industry Benchmarks'!$A$2:$A$8, 0)) -> 35 | C18: =INDEX('Industry Benchmarks'!$P$2:$P$8, MATCH('User Inputs'!$B$2, 'Industry Benchmarks'!$A$2:$A$8, 0)) -> 35 | D18: Cost of Vinturas platform as % of savings
A19: Alliance efficiency (inter-facility reduction) | B19: =INDEX('Industry Benchmarks'!$Q$2:$Q$8, MATCH('User Inputs'!$B$2, 'Industry Benchmarks'!$A$2:$A$8, 0)) -> 0.65 | C19: =INDEX('Industry Benchmarks'!$Q$2:$Q$8, MATCH('User Inputs'!$B$2, 'Industry Benchmarks'!$A$2:$A$8, 0)) -> 0.65 | D19: Reduction in internal transfers via alliance
A20: Emission reduction % (logistics) | B20: =INDEX('Industry Benchmarks'!$T$2:$T$8, MATCH('User Inputs'!$B$2, 'Industry Benchmarks'!$A$2:$A$8, 0)) -> 3000000 | C20: =INDEX('Industry Benchmarks'!$T$2:$T$8, MATCH('User Inputs'!$B$2, 'Industry Benchmarks'!$A$2:$A$8, 0)) -> 3000000 | D20: Reduction in logistics emissions
A21: Scope3 emission intensity (t per $M) | B21: =INDEX('Industry Benchmarks'!$AE$2:$AE$8, MATCH('User Inputs'!$B$2, 'Industry Benchmarks'!$A$2:$A$8, 0)) -> 0.7 | C21: =INDEX('Industry Benchmarks'!$AE$2:$AE$8, MATCH('User Inputs'!$B$2, 'Industry Benchmarks'!$A$2:$A$8, 0)) -> 0.7 | D21: Emission intensity factor
A22: Total Scope 3 emissions (t) | B22: ='Derived Metrics'!B15 -> 77000 | D22: Baseline Scope3 emissions scaled by revenue
A23: Reduced tons (Scope 3) | B23: ='Derived Metrics'!B16 -> 7854 | D23: Tons of CO2e reduced via logistics improvement
A24: Emission benefit (USD) | B24: ='Derived Metrics'!B17 -> 667590 | D24: CO2 reduction benefit valued at carbon price
A25: ESG audit benefit (USD) | B25: ='Derived Metrics'!B18 -> 810000 | D25: Penalty avoidance due to ESG compliance
A26: Total Recurring EBIT Impact | B26: ='Savings & Benefits'!B11 -> 2791026 | D26: Annual recurring savings before platform cost
A27: Total One-time Cash Benefit | B27: ='Savings & Benefits'!B15 -> 9961095.9 | D27: Cash released by inventory reduction
A28: Total One-time Cost Avoidance | B28: ='Savings & Benefits'!B25 -> 1730004.2 | D28: Avoided capex and penalties
A29: Net Recurring EBIT after Platform Cost | B29: ='Savings & Benefits'!B31 -> 2372372.1 | D29: Net recurring EBIT after deducting platform cost
A30: Carbon price (USD/ton) | B30: =INDEX('Industry Benchmarks'!$U$2:$U$8, MATCH('User Inputs'!$B$2, 'Industry Benchmarks'!$A$2:$A$8, 0)) -> 0.15 | C30: =INDEX('Industry Benchmarks'!$U$2:$U$8, MATCH('User Inputs'!$B$2, 'Industry Benchmarks'!$A$2:$A$8, 0)) -> 0.15 | D30: Carbon price input vs benchmark
A31: Logistics share of scope 3 | B31: =INDEX('Industry Benchmarks'!$W$2:$W$8, MATCH('User Inputs'!$B$2, 'Industry Benchmarks'!$A$2:$A$8, 0)) -> 1500000 | C31: =INDEX('Industry Benchmarks'!$W$2:$W$8, MATCH('User Inputs'!$B$2, 'Industry Benchmarks'!$A$2:$A$8, 0)) -> 1500000 | D31: Share of emissions that are logistics
A32: ESG audit penalty (USD) | B32: =INDEX('Industry Benchmarks'!$Y$2:$Y$8, MATCH('User Inputs'!$B$2, 'Industry Benchmarks'!$A$2:$A$8, 0)) -> 0.9 | C32: =INDEX('Industry Benchmarks'!$Y$2:$Y$8, MATCH('User Inputs'!$B$2, 'Industry Benchmarks'!$A$2:$A$8, 0)) -> 0.9 | D32: Average ESG penalty
A33: ESG risk probability | B33: =INDEX('Industry Benchmarks'!$AF$2:$AF$8, MATCH('User Inputs'!$B$2, 'Industry Benchmarks'!$A$2:$A$8, 0)) -> 0.002 | C33: =INDEX('Industry Benchmarks'!$AF$2:$AF$8, MATCH('User Inputs'!$B$2, 'Industry Benchmarks'!$A$2:$A$8, 0)) -> 0.002 | D33: Probability of ESG penalty
A34: ESG avoidance probability | B34: =INDEX('Industry Benchmarks'!$AG$2:$AG$8, MATCH('User Inputs'!$B$2, 'Industry Benchmarks'!$A$2:$A$8, 0)) -> 0.15 | C34: =INDEX('Industry Benchmarks'!$AG$2:$AG$8, MATCH('User Inputs'!$B$2, 'Industry Benchmarks'!$A$2:$A$8, 0)) -> 0.15 | D34: Probability of avoiding ESG penalty

Sheet Output Summary
A1: Vinturas ROI Summary
A3: Metric | B3: Value
A4: Sales Growth (sum of service uplifts) | B4: ='Savings & Benefits'!B2 + 'Savings & Benefits'!B3 -> 663600
A5: Total Recurring EBIT Impact | B5: ='Savings & Benefits'!B20 -> 4032000
A6: Net Recurring EBIT after Platform Cost | B6: ='Savings & Benefits'!B20 - ('Savings & Benefits'!B20+'Savings & Benefits'!B21+'Savings & Benefits'!B25) * INDEX('Industry Benchmarks'!$P$2:$P$8, MATCH('User Inputs'!$B$2, 'Industry Benchmarks'!$A$2:$A$8, 0)) -> -2.5361575e+08
A7: Total One-time Cash Benefit | B7: ='Savings & Benefits'!B21 -> 1599360
A8: Total One-time Cost Avoidance | B8: ='Savings & Benefits'!B25 -> 1730004.2
A10: Analysis Narrative
A11: This model scales Scope 3 emissions based on company revenue and industry emission intensity. Key savings include freight, customs, expedite, and planner productivity, while one-time benefits come from inventory release and capex avoidance. Net recurring EBIT after platform cost reflects the sustainable margin improvement expected from a full Vinturas implementation.

Sheet Industry Benchmark Reference
A1: Vinturas ROI Model: Complete Industry Benchmark Parameter Reference & Validation Report
A2: Version 6.0 – October 30, 2025
A3: Prepared by: Miro BABOL
